Workbook

Sheet Project Data
A1: Project Name | B1: Zero Downtime Linux Updates
A3: Online team meeting | B3: https://tu-berlin.zoom-x.de/j/2406759921?pwd=ahCbJqSuz3RaljImkCzVHeSgzqLg2k.1
B4: 3
A5: Production system (if any)
A6: Test system (if any) | B6: ...
A8: GitHub repository | B8: https://github.com/amosproj/amos2026ss01-zero-downtime-linux-updates
A9: GitHub feature board | B9: https://github.com/orgs/amosproj/projects/97
A10: GitHub imp-squared backlog | B10: https://github.com/orgs/amosproj/projects/101
A12: Position of T-shirt logo | B12: Upper Torso Right Small
A13: Link to logo for black T-shirt | B13: https://github.com/amosproj/amos2026ss01-zero-downtime-linux-updates/blob/main/Deliverables/sprint-01/team-logo.svg
A14: Link to logo for white T-shirt | B14: https://github.com/amosproj/amos2026ss01-zero-downtime-linux-updates/blob/main/Deliverables/sprint-01/team-logo.svg
A16: Additional materials | B16: https://discord.gg/cBnpkJKNEu
A18: Team maling list | B18: oss-amos-proj1@lists.fau.de
A19: Happines Index | B19: https://happy.uni1.de/login
A20: Planning Poker | B20: https://planningpokeronline.com/t2YLAtlYDVOOcjJW6gzq/

Sheet Project Team
A1: Last Name | B1: First Name | C1: GitHub User Name | D1: Email Address
A2: Auer | B2: Katharina | C2: KathiAurina | D2: katharina.auer@fau.de
A3: Böhm | B3: Luca | C3: QW3RAT | D3: luca.boehm@fau.de
A4: Durand | B4: Patrick | C4: patridu | D4: patrick.durand@fau.de
A5: Freymann | B5: Jaroslav | C5: IFrey | D5: jaroslav.freymann@fu-berlin.de
A6: Friedrich | B6: Jeremias | C6: Jerry1098 | D6: jeremias.friedrich@fau.de
A7: Klem | B7: Luca | C7: Lugga19 | D7: luca.klem@fau.de
A8: Meusling | B8: Patrick | C8: SirGankalot | D8: meusling@campus.tu-berlin.de
A9: Reinel | B9: Moritz | C9: moritz-reinel | D9: mo.ritz@fau.de
A10: Schütz | B10: Julian | C10: Beambamacrys | D10: julian.schuetz@fau.de
A11: Zobel | B11: Simeon | C11: uzantome | D11: git@uzanto.me

Sheet Role Assignments
C1: Product Owner
A2: # | B2: Meeting Day | C2: Review | D2: Planning | E2: Software Developer | F2: Release Manager | G2: Scrum Master | H2: Comment
A3: 1 | B3: 46127 | C3: Böhm | D3: Klem | E3: Everyone else | F3: N/A | G3: Patrick Meusling
A4: 2 | B4: 46134 | C4: Klem | D4: Böhm | E4: Everyone else | F4: Jeremias Friedrich | G4: Patrick Meusling
A5: 3 | B5: 46141 | C5: Böhm | D5: Klem | E5: Everyone else | F5: Julian Schütz | G5: Patrick Meusling
A6: 4 | B6: 46148 | C6: Klem | D6: Böhm | E6: Everyone else | F6: Katharina Auer | G6: Patrick Meusling
A7: 5 | B7: 46155 | C7: Böhm | D7: Klem | E7: Everyone else | F7: Moritz Reinel | G7: Patrick Meusling
A8: 6 | B8: 46162 | C8: Klem | D8: Böhm | E8: ... | F8: Katharina Auer | G8: Patrick Meusling
A9: 7 | B9: 46169 | C9: Böhm | D9: Klem | F9: Jaroslav Freymann | G9: Patrick Meusling | H9: Mid-term due
A10: 8 | B10: 46176 | C10: Klem | D10: Böhm | F10: Patrick Durand | G10: Patrick Meusling
A11: 9 | B11: 46183 | C11: Böhm | D11: Klem | F11: Moritz Reinel | G11: Patrick Meusling
A12: 10 | B12: 46190 | C12: Klem | D12: Böhm | F12: Patrick Durand | G12: Patrick Meusling
A13: 11 | B13: 46197 | C13: Böhm | D13: Klem | F13: Julian Schütz | G13: Patrick Meusling
A14: 12 | B14: 46204 | C14: Klem | D14: Böhm | F14: Jeremias Friedrich | G14: Patrick Meusling
A15: 13 | B15: 46211 | C15: Böhm | D15: Klem | F15: Jaroslav Freymann | G15: Patrick Meusling
A16: 14 | B16: 46218 | C16: Klem | D16: Böhm | F16: Simeon Zobel | G16: Patrick Meusling | H16: Demo day!
A17: 15 | B17: 46225 | C17: Böhm | D17: Klem | F17: Simeon Zobel | G17: Patrick Meusling | H17: Retrospective
A19: Product owners, software developers, and Scurm Master are set and ideally don't change over time; the critical part is the Release Manager role you need to define here

Sheet Team Contract
A1: Goals | B1: Aquire new skills
B2: Produce a functioning and valuable product
A3: Meeting norms | B3: We show up on time
B4: Devs make sure to try to understand the new sprints tickets before the team meeting
B5: POs provide a summary of industry partner meeting
A6: Working norms | B6: Clean, testable code with clear commit messages, code comments
B7: We respect other people's work
B8: PRs must be ready for review by Tuesday 6:00 am. Tuesdays are reserved for review and merging
A9: Coordination norms | B9: Separate branches for issues, branches only get merged via Merge Requests, second person to review
B10: We balance workload among the team
A11: Communication norms | B11: We regularly check the corresponding channels
B12: We make sure to communicate possible problems as early as possible (absence, etc.)
B13: We communicate constructively
A14: Consideration norms | B14: We discuss issues openly
B15: We vote in case we can't reach a consensus
A16: Cont. improvement norms | B16: We encourage critique and improvement efforts
B17: We reach out for help early enough to still finish our tasks
A18: Rewards | B18: Favorite Drink
B19: Wear a cool hat or glasses during meetings
A20: Sanctions | B20: Publish a stackoverflow answer
A22: Signatures
A24: Scrum Master | B24: Patrick Meusling
A25: Product owner | B25: Luca Klem
A26: Product owner | B26: Luca Böhm
A27: Software developer | B27: Katharina Auer
A28: Software developer | B28: Jaroslav Freymann
A29: Software developer | B29: Julian Schütz
A30: Software developer | B30: Patrick Durand
A31: Software developer | B31: Moritz Reinel
A32: Software developer | B32: Simeon Zobel
A33: Software developer | B33: Jeremias Friedrich

Sheet Product Goal
A1: Product Vision | B1: Project Mission
A3: To provide industrail manufacturers with an open-source, simple, and secure management structrure for edge devices and applications that gurantees operational continuity. This allows organizations like Weber to declare operating system (Fedora IoT) version and application versions they want to run on an individual device or a whole fleet of devices. The product will roll out the target configuration to devices while maintaining highest standards of safety, regulatory compliance (NIS2), and ensuring zero-downtime operations for critical machinery. | B3: To design and develop a secure, Rust-based edge orchestrator for Weber’s Edge IPC that enables near zero-downtime updates for both the operating system and application layers. Our mission is to implement a management agent that leverages Fedora IoT, bootc, and Podman to ensure system updates and reliability. We create a cloud containing a database, which manages edge device infromation, and the running and desired OS and application versions. Users should be able to create, read, update, and delete devices, device groups, OS, and application information.

Sheet Product Glossary
A1: Term | B1: Definition
A2: Edge Device/ Edge IPC | B2: An industrial Inter-Process Communication (IPC) hardware asset deployed on the factory floor on which our project runs.
A3: Edge Agent | B3: The sytem component that is running on the Edge IPC and controlls Updates and Communication. This includes Orchestrator, Download manager, and Health checks
A4: Orchestrator | B4: The central, automated controller within the Edge Agent that coordinates the execution of all local update activities. It is responsible for executing the update cycle by interpreting the remote configuration, monitoring the local system status, and sequentially triggering download, verification, and installation workflows to align the physical device with the cloud's target state.
A5: Device Identity | B5: A unique identifier permanently bound to a physical Edge Device, derived directly from its onboard hardware.
A6: Image | B6: A complete representation of a software layer packaged as a containerized asset ready for deployment.
A7: Download Manager | B7: A component within the Edge Agent tasked with fetching the required state of OS and applications on the device from the Cloud.
A8: Inventory Database | B8: Database in the Cloud that stores all information of the Edge Device, Appcations, and OS Versions. On top of that it stores the current deployed and the required OS and application version for each Edge Device.
A10: Rollback | B10: An automated emergency recovery operation that instantly reverts an Edge Device to its previously functional Operating System Image or Application Stack upon a post-update health check failure.
A11: Health Check | B11: A set of automated local test scripts executed immediately after a system switch or reboot to verify the functional correctness of critical device services before confirming an update as successful.
A12: Fleet | B12: The total of all edge devices that are managed by one company/user.
A13: Database | B13: Central Database where information about Edge Devices is gathered. This includes but isnt limited to: OS version, Host Info, Tenant, Group
... A16: Cloud | B16: Includes Invetory Database and APIs to communicate with which the user and Edge IPC can communicate.

Sheet Sprint Goals
A1: Sprint # | B1: Sprint goal
A2: 1 | B2: None
A3: =A2+1 -> 2 | B3: None
A4: =A3+1 -> 3 | B4: None
A5: =A4+1 -> 4 | B5: Optional
A6: =A5+1 -> 5 | B6: Enable OS update swapping
A7: =A6+1 -> 6 | B7: Database interaction with the user and Edge IPC is enabled
A8: =A7+1 -> 7 | B8: ='Final Project Release plan'!B9 -> Enhance database functionality and logging
A9: =A8+1 -> 8 | B9: ='Final Project Release plan'!B10 -> Integration Testing and Test Environment
A10: =A9+1 -> 9 | B10: ='Final Project Release plan'!B11 -> Save device and application Logs in Database
A11: =A10+1 -> 10 | B11: ='Final Project Release plan'!B12 -> Provide Logs and Streaming for Users
A12: =A11+1 -> 11 | B12: ='Final Project Release plan'!B13 -> First Demo preperations
A13: =A12+1 -> 12 | B13: ='Final Project Release plan'!B14 -> Finalize Project and Demo preperation
A14: =A13+1 -> 13 | B14: ='Final Project Release plan'!B15 -> Prepare Handover
A15: =A14+1 -> 14 | B15: ='Final Project Release plan'!B16
A16: =A15+1 -> 15 | B16: ='Final Project Release plan'!B17

Sheet Velocity Tracking
A1: Sprint # | B1: Story Points Realized
A2: 1 | B2: ='Mid-Project Release plan'!F9 -> 0
A3: =A2+1 -> 2 | B3: ='Mid-Project Release plan'!F10 -> 12
A4: =A3+1 -> 3 | B4: ='Mid-Project Release plan'!F11 -> 19
A5: =A4+1 -> 4 | B5: ='Mid-Project Release plan'!F12 -> 15
A6: =A5+1 -> 5 | B6: ='Mid-Project Release plan'!F13 -> 25
A7: =A6+1 -> 6 | B7: ='Mid-Project Release plan'!F14 -> 21
A8: =A7+1 -> 7 | B8: ='Final Project Release plan'!F9 -> 11
A9: =A8+1 -> 8 | B9: ='Final Project Release plan'!F10 -> 19
A10: =A9+1 -> 9 | B10: ='Final Project Release plan'!F11 -> 24
A11: =A10+1 -> 10 | B11: ='Final Project Release plan'!F12 -> 0
A12: =A11+1 -> 11 | B12: ='Final Project Release plan'!F13 -> 0
A13: =A12+1 -> 12 | B13: ='Final Project Release plan'!F14 -> 0
A14: =A13+1 -> 13 | B14: ='Final Project Release plan'!F15 -> 0
B18: PLEASE CREATE THE VELOCITY CHART ON A NEW TAB USING THE DATA FROM THIS TAB

Sheet Velocity Chart

Sheet Mid-Project Release plan
A1: Sprint | B1: Goal | C1: Feature Name | D1: Est. size | E1: Est. remaining | F1: Real size | G1: Real remaining
A3: Release
A5: Total | D5: =sum(D8:D15) -> 86 | E5: =D5 -> 86 | F5: =sum(F8:F15) -> 92
A7: Sprints
E8: Estimated burn-down | G8: Real burn-down
A9: 1 | B9: ='Sprint Goals'!B2 -> None | D9: =SUM(D18) -> 0 | E9: =$D$5 -> 86 | F9: =SUM(F18) -> 0 | G9: =$F$5 -> 92
A10: =A9+1 -> 2 | B10: ='Sprint Goals'!B3 -> None | D10: =SUM(D24:D29) -> 12 | E10: =E9-D10 -> 74 | F10: =SUM(F24:F29) -> 12 | G10: =G9-F10 -> 80
A11: =A10+1 -> 3 | B11: ='Sprint Goals'!B4 -> None | D11: =SUM(D31:D35) -> 16 | E11: =E10-D11 -> 58 | F11: =SUM(F31:F35) -> 19 | G11: =G10-F11 -> 61
A12: 4 | B12: ='Sprint Goals'!B5 -> Optional | D12: =SUM(D37:D41) -> 20 | E12: =E11-D12 -> 38 | F12: =SUM(F37:F41) -> 15 | G12: =G11-F12 -> 46
A13: 5 | B13: ='Sprint Goals'!B6 -> Enable OS update swapping | D13: =SUM(D43:D49) -> 21 | E13: =E12-D13 -> 17 | F13: =SUM(F43:F49) -> 25 | G13: =G12-F13 -> 21
A14: 6 | B14: ='Sprint Goals'!B7 -> Database interaction with the user and Edge IPC is enabled | D14: =SUM(D51:D55) -> 17 | E14: =E13-D14 -> 0 | F14: =SUM(F51:F55) -> 21 | G14: =G13-F14 -> 0
A16: Features
A18: =A9 -> 1 | B18: =B9 -> None
A24: =A10 -> 2 | B24: =B10 -> None | C24: Review different Linux Distros | D24: 3 | F24: 3
C25: Review Backup options | D25: 2 | F25: 2
C26: Setup shared dev environment | D26: 2 | F26: 2
C27: Review options for zero downtime update | D27: 2 | F27: 2
C28: Initialize SBOM and Software Architecture | D28: 1 | F28: 1
C29: Review how TPM can be used | D29: 2 | F29: 2
A31: =A11 -> 3 | B31: =B11 -> None | C31: HTTPS Download Manager | D31: 3 | F31: 3
C32: API Protocoll & Mock Cloud | D32: 3 | F32: 5
C33: Setup DCO & CI Pipeline | D33: 3 | F33: 5
C34: Edge IPC Orchestrator | D34: 5 | F34: 5
C35: Signature Verification | D35: 2 | F35: 1
A37: 4 | B37: =B12 -> Optional | C37: Setup Cargo Workspace | D37: 2 | F37: 2
C38: rpm-ostree OS Update Controller | D38: 2 | F38: 2
C39: Post-Update Health Checks | D39: 5 | F39: 3
C40: Containerized Image Delivery | D40: 8 | F40: 5
C41: Device Inventory MVP | D41: 3 | F41: 3
A43: 5 | B43: =B13 -> Enable OS update swapping | C43: Build Process Video | D43: 2 | F43: 2
C44: Orchestrator check for update | D44: 3 | F44: 5
C45: Application Stack Controller | D45: 3 | F45: 5
C46: Refactor: bootc wrapper | D46: 3 | F46: 3
C47: rpm-ostree OS Update Controller | D47: 2 | F47: 2
C48: Update Documentation and Architecture | D48: 3 | F48: 3
C49: Setup Inventory Database | D49: 5 | F49: 5
A51: 6 | B51: =B14 -> Database interaction with the user and Edge IPC is enabled | C51: Create Scheme for Database and API calls | D51: 3 | F51: 3
C52: Refactor: Orchestrator initiates updates | D52: 3 | F52: 5
B53: =B15 | C53: Edge IPC to Cloud API for Database updates | D53: 3 | F53: 3
B54: =B16 | C54: User to Cloud API for Database Updates | D54: 3 | F54: 5
...

Sheet Mid-Project Burndown Chart

Sheet Final Project Release plan
A1: Sprint | B1: Goal | C1: Feature Name | D1: Est. size | E1: Est. remaining | F1: Real size | G1: Real remaining
A3: Release
A5: Total | D5: =sum(D8:D17) -> 135 | E5: =D5 -> 135
A7: Sprints
E8: Estimated burn-down | G8: Real burn-down
A9: 7 | B9: Enhance database functionality and logging | D9: =SUM(D21:D26) -> 15 | E9: =$D$5-D9 -> 120 | F9: =SUM(F21:F26) -> 11 | G9: =$D$5-F9 -> 124
A10: 8 | B10: Integration Testing and Test Environment | D10: =SUM(D28:D31) -> 19 | E10: =E9-D10 -> 101 | F10: =SUM(F28:F31) -> 19 | G10: =G9-F10 -> 105
A11: =A10+1 -> 9 | B11: Save device and application Logs in Database | D11: =SUM(D33:D37) -> 21 | E11: =E10-D11 -> 80 | F11: =SUM(F33:F37) -> 24 | G11: =G10-F11 -> 81
A12: 10 | B12: Provide Logs and Streaming for Users | D12: =SUM(D39:D46) -> 24 | E12: =E11-D12 -> 56 | F12: =SUM(F39:F46) -> 0 | G12: =G11-F12 -> 81
A13: 11 | B13: First Demo preperations | D13: =SUM(D48:D56) -> 23 | E13: =E12-D13 -> 33 | F13: =SUM(F48:F50) -> 0 | G13: =G12-F13 -> 81
A14: 12 | B14: Finalize Project and Demo preperation | D14: =SUM(D58:D62) -> 18 | E14: =E13-D14 -> 15 | F14: =sum(F38:F47) -> 0 | G14: =G13-F14 -> 81
A15: 13 | B15: Prepare Handover | D15: =SUM(D64:D68) -> 15 | E15: =E14-D15 -> 0 | F15: =sum(F39:F48) -> 0 | G15: =G14-F15 -> 81
A18: Features
A20: =A9 -> 7 | B20: =B9 -> Enhance database functionality and logging
C21: Refactor: Introduce DTO | D21: 3 | F21: 3
C22: OS Image creation of different versions | D22: 3 | F22: 2
C23: Add Heartbeats | D23: 1 | F23: 1
C24: Research: Timestamp for DB changes | D24: 3 | F24: 1
C25: Signature Verification of image delivery | D25: 3 | F25: 2
C26: Add paging to device/group/application information | D26: 2 | F26: 2
A27: =A10 -> 8 | B27: =B10 -> Integration Testing and Test Environment
C28: Create test setup | D28: 8 | F28: 8
C29: Create Integration tests | D29: 5 | F29: 5
C30: Authentication for User API | D30: 3 | F30: 3
C31: Research: Solution for storing time sensitive data | D31: 3 | F31: 3
A32: 9 | B32: =B11 -> Save device and application Logs in Database
C33: Provide device logging function for storing logs in database | D33: 2 | F33: 3
C34: TPM-based Device Indentity Verification at Edge IPC-Cloud API | D34: 5 | F34: 8
C35: Log timestamp and user information for database changes | D35: 3 | F35: 3
C36: Monitor and Mange Podman Containers | D36: 8 | F36: 5
C37: Create API for time sensitive data | D37: 3 | F37: 5
A38: 10 | B38: =B12 -> Provide Logs and Streaming for Users
C39: Store App Config in databse | D39: 5
C40: Store Podman logs in database | D40: 3
C41: Store Device Logs in Database | D41: 2
C42: Refactor Orchestrator | D42: 2
C43: Hardware deployment | D43: 3
C44: Adapt database to support changelogs in UI | D44: 5
C45: Testing: Adapt Integration Testing so that TPM works with it | D45: 1
C46: Testing: Improve test setup so that changing binary in vm is easier | D46: 3
...

Sheet Final Project Burndown Chart
A1: Sprint | B1: Goal | C1: Feature Name | D1: Est. size | E1: Est. remaining | F1: Real size | G1: Real remaining
A34: =A11
A35: 10
A36: 11
A37: 12
A38: 13
A39: 14
C41: PLEASE CREATE THE BURNDOWN CHART ON A NEW TAB USING THE DATA FROM THIS TAB

Sheet Definition of Done
A1: # | B1: Feature Definition of Done | C1: Sprint Release Definition of Done | D1: Project Release Definition of Done
B2: All Acceptance criterias defined in the backlog item are met and verified
B3: Work done is pushed to the Github repository
B4: For each backlog item a branch is created
B5: Pull requests are created for each branch
B6: Pull requests are reviewed
B7: Corresponding branches are merged
B8: Software Bill of Materials in the planning document is updated if new dependencies were added
B9: The Wiki Section/Documentation corresponding to the work done is updated
B10: Unit tests are written for all new logic
B11: All unit tests must pass successfully in the CI pipeline
B12: Code passes cargo fmt (style) and cargo clippy (linting)
B13: All Developers assigned to a backlog item must communicate and coordinate with each other to complete the task
C14: All features merged into the main branch; the CI pipeline is "Green"
C15: Release candidates with a working and meaningful update to the previous sprint is tagged
C16: Previously established features must continue to work.
D17: All automated tests and validation checks for the developed components pass without errors
D18: A single-click deployment/flashable image for the selected hardware is available
D19: User documentation (usage examples, configuration steps, expected outputs) is finalized and up to date
D20: All open-source licenses are documented and compliant
D21: A "Handover Document" for Weber is completed in the Wiki
D22: The final release has been reviewed and approved by all project team members and the industry partner

Sheet Documentation
A1: Type | B1: Link / reference

Sheet Planning Poker
A1: ='Project Team'!A1 -> Last Name | B1: ='Project Team'!B1 -> First Name | C1: Value
A2: ='Project Team'!A2 -> Auer | B2: ='Project Team'!B2 -> Katharina | C2: 0 | E2: =average(C2:C10) -> 0 | F2: =if(stdev(C2:C7) > 0,"NOK", "OK") -> OK
A3: =#REF! -> #REF! | B3: =#REF! -> #REF! | C3: 0
A4: =#REF! -> #REF! | B4: =#REF! -> #REF!
A5: =#REF! -> #REF! | B5: =#REF! -> #REF!
A6: =#REF! -> #REF! | B6: =#REF! -> #REF! | E6: 0 | F6: No size
A7: =#REF! -> #REF! | B7: =#REF! -> #REF! | E7: 1 | F7: Trivial size
A8: =#REF! -> #REF! | B8: =#REF! -> #REF! | E8: 2 | F8: Small size
A9: =#REF! -> #REF! | B9: =#REF! -> #REF! | E9: 3 | F9: Medium size
A10: =#REF! -> #REF! | B10: =#REF! -> #REF! | E10: 5 | F10: Large size
E11: 8 | F11: Very large size
E12: 13 | F12: Too large (size)
A14: How to play planning poker
A16: 1. Everyone type their number into their value field, don't hit return yet
A17: 2. Someone, perhaps a product owner, count down 3.. 2.. 1..
A18: 3. Then, everyone hit return to submit their value

Sheet Bill of Materials
A1: # | B1: Context | C1: Name | D1: Version | E1: License | F1: Comment
A2: 1 | B2: OS | C2: Fedora Linux | D2: 44 | E2: MIT
A3: 2 | B3: Language | C3: Rust | D3: 1.95.0 (latest stable) | E3: MIT/Apache 2.0
A4: 3 | B4: Rust Toolchain | C4: rustc | D4: 1.95.0 (latest stable) | E4: MIT/Apache 2.0
A5: 4 | B5: Rust Buildsystem | C5: cargo | D5: 1.95.0 (latest stable) | E5: MIT/Apache 2.0
A6: 5 | B6: Rust Standard library | C6: rust-std | D6: 1.95.0 (latest stable) | E6: MIT/Apache 2.0
A7: 6 | B7: Rust Security/Audit (Dev Process) | C7: cargo-audit | D7: 0.22.1 | E7: MIT/Apache 2.0
A8: 7 | B8: Runtime | C8: Container Engine (TBD) | D8: TBD | E8: TBD
A9: 8 | B9: Security | C9: TPM (TBD) | D9: TBD | E9: TBD
A10: 9 | B10: Update | C10: A/B Update Framework (TBD) | D10: TBD | E10: TBD
A11: 11 | B11: Publish Process | C11: Github Actions | D11: N/A | E11: N/A
A12: 12 | B12: Rust Package | C12: config | D12: 0.15.22 | E12: MIT/Apache 2.0 | F12: https://github.com/rust-cli/config-rs
A13: 13 | B13: Rust Package | C13: env_logger | D13: 0.11.10 | E13: MIT/Apache 2.0 | F13: https://github.com/rust-cli/env_logger
A14: 14 | B14: Rust Package | C14: log | D14: 0.4.29 | E14: MIT/Apache 2.0 | F14: https://github.com/rust-lang/log
A15: 15 | B15: Rust Package | C15: serde | D15: 1.0.228 | E15: MIT/Apache 2.0 | F15: https://github.com/serde-rs/serde
A16: 16 | B16: Rust Package | C16: tokio | D16: 1.52.1 | E16: MIT | F16: https://github.com/tokio-rs/tokio
A17: 17 | B17: Rust Package | C17: reqwest | D17: 0.13.3 | E17: MIT/Apache 2.0 | F17: https://github.com/seanmonstar/reqwest
A18: 18 | B18: Rust Package | C18: anyhow | D18: 1.0.102 | E18: MIT/Apache 2.0 | F18: https://github.com/dtolnay/anyhow
A19: 19 | B19: Rust Package | C19: futures-util | D19: 0.3.32 | E19: MIT/Apache 2.0 | F19: https://github.com/rust-lang/futures-rs
A20: 20 | B20: Rust Package | C20: base64 | D20: 0.22 | E20: MIT/Apache 2.0 | F20: https://github.com/marshallpierce/rust-base64
A21: 21 | B21: Rust Package | C21: Serde JSON | D21: 1 | E21: MIT/Apache 2.0 | F21: https://github.com/serde-rs/json
A22: 22 | B22: Rust Package | C22: ed25519-dalek | D22: 2.2.0 | E22: BSD-3-Clause | F22: https://github.com/dalek-cryptography/curve25519-dalek
A23: 23 | B23: Rust Package | C23: clap | D23: 4.6.1 | E23: MIT/Apache 2.0 | F23: https://github.com/clap-rs/clap
A24: 24 | B24: Rust Package | C24: async-trait | D24: 0.1 | E24: MIT/Apache 2.0
A25: 25 | B25: Rust Package | C25: tracing | D25: 0.1.44 | E25: MIT | F25: https://github.com/tokio-rs/tracing
A26: 26 | B26: Rust Package | C26: sea-orm, sea-orm-migration | D26: 2.0.0-rc | E26: MIT/Apache 2.0 | F26: https://github.com/SeaQL/sea-orm
A27: 27 | B27: Rust Package | C27: jsonwebtoken | D27: 10.4.0 | E27: MIT | F27: https://github.com/Keats/jsonwebtoken
A28: 28 | B28: Rust Package | C28: tss_esapi | D28: 7.7.0 | E28: Apache 2.0 | F28: https://github.com/parallaxsecond/rust-tss-esapi
